const f = () =>{
try{

    let a = 0   
    //console.log(c)
    console.log("Program succesefully running")
    return


}

catch(err){
    console.log("this is an error")
    console.log(program)
}


/*The code in the finally block will always be executed, whether an error occurs or not.
The finally block is useful for cleanup tasks, */
finally{
    console.log("i am a good boy")
    /* close the file
    exit the loop
    write the log  file*/
}


}

f()